Workbook
Name Slicer_Nationality_Type: #N/A
Name Slicer_Team_Name: #N/A
Name Slicer_Venue_Name1: #N/A
Name Slicer_Venue_Name2: #N/A
Name Slicer_Win_Type: #N/A

Sheet fact_player
A1: Match_ID | B1: Player_ID | C1: Runs | D1: Balls_Faced | E1: Fours | F1: Sixes | G1: Strike_Rate | H1: Overs_Bowled | I1: Runs_Conceded | J1: Wickets | K1: Economy | L1: Check_ID | M1: Column1
A2: M001 | B2: P006 | C2: 58 | D2: 32 | E2: 6 | F2: 3 | G2: 181.25 | H2: 0 | I2: 0 | J2: 0 | K2: 0 | L2: =COUNTIF(dim_player!A:A, A2) -> 0 | M2: =COUNTIF(dim_player!A:A, B2) -> 1
A3: M001 | B3: P010 | C3: 72 | D3: 50 | E3: 5 | F3: 2 | G3: 144 | H3: 0 | I3: 0 | J3: 0 | K3: 0 | L3: =COUNTIF(dim_player!A:A, A3) -> 0 | M3: =COUNTIF(dim_player!A:A, B3) -> 1
A4: M001 | B4: P012 | C4: 0 | D4: 0 | E4: 0 | F4: 0 | G4: 0 | H4: 4 | I4: 28 | J4: 2 | K4: 7 | L4: =COUNTIF(dim_player!A:A, A4) -> 0 | M4: =COUNTIF(dim_player!A:A, B4) -> 1
A5: M002 | B5: P033 | C5: 95 | D5: 58 | E5: 10 | F5: 4 | G5: 163.79 | H5: 0 | I5: 0 | J5: 0 | K5: 0 | L5: =COUNTIF(dim_player!A:A, A5) -> 0 | M5: =COUNTIF(dim_player!A:A, B5) -> 1
A6: M002 | B6: P018 | C6: 45 | D6: 35 | E6: 4 | F6: 1 | G6: 128.57 | H6: 0 | I6: 0 | J6: 0 | K6: 0 | L6: =COUNTIF(dim_player!A:A, A6) -> 0 | M6: =COUNTIF(dim_player!A:A, B6) -> 1
A7: M003 | B7: P015 | C7: 34 | D7: 18 | E7: 2 | F7: 3 | G7: 188.89 | H7: 4 | I7: 38 | J7: 3 | K7: 9.5 | L7: =COUNTIF(dim_player!A:A, A7) -> 0 | M7: =COUNTIF(dim_player!A:A, B7) -> 1
A8: M003 | B8: P027 | C8: 0 | D8: 0 | E8: 0 | F8: 0 | G8: 0 | H8: 4 | I8: 30 | J8: 2 | K8: 7.5 | L8: =COUNTIF(dim_player!A:A, A8) -> 0 | M8: =COUNTIF(dim_player!A:A, B8) -> 1
A9: M004 | B9: P022 | C9: 65 | D9: 40 | E9: 7 | F9: 2 | G9: 162.5 | H9: 0 | I9: 0 | J9: 0 | K9: 0 | L9: =COUNTIF(dim_player!A:A, A9) -> 0 | M9: =COUNTIF(dim_player!A:A, B9) -> 1
A10: M004 | B10: P002 | C10: 0 | D10: 0 | E10: 0 | F10: 0 | G10: 0 | H10: 3.2 | I10: 25 | J10: 3 | K10: 7.5 | L10: =COUNTIF(dim_player!A:A, A10) -> 0 | M10: =COUNTIF(dim_player!A:A, B10) -> 1
A11: M005 | B11: P025 | C11: 88 | D11: 52 | E11: 8 | F11: 3 | G11: 169.23 | H11: 0 | I11: 0 | J11: 0 | K11: 0 | L11: =COUNTIF(dim_player!A:A, A11) -> 0 | M11: =COUNTIF(dim_player!A:A, B11) -> 1
A12: M005 | B12: P010 | C12: 5 | D12: 7 | E12: 0 | F12: 0 | G12: 71.43 | H12: 0 | I12: 0 | J12: 0 | K12: 0 | L12: =COUNTIF(dim_player!A:A, A12) -> 0 | M12: =COUNTIF(dim_player!A:A, B12) -> 1
A13: M006 | B13: P016 | C13: 18 | D13: 10 | E13: 1 | F13: 1 | G13: 180 | H13: 4 | I13: 22 | J13: 2 | K13: 5.5 | L13: =COUNTIF(dim_player!A:A, A13) -> 0 | M13: =COUNTIF(dim_player!A:A, B13) -> 1
... A202: M140 | B202: P033 | C202: 60 | D202: 35 | E202: 6 | F202: 3 | G202: 171.43 | H202: 0 | I202: 0 | J202: 0 | K202: 0 | L202: =COUNTIF(dim_player!A:A, A202) -> 0 | M202: =COUNTIF(dim_player!A:A, B202) -> 1

Sheet Team_Summary
A3: Row Labels | B3: Team Appearence | C3: Matches Played | K3: Row Labels | L3: Total Runs | V3: Row Labels | W3: Count of Match_ID
A4: Chennai Super Kings (CSK) | B4: 14 | C4: 9 | K4: Chennai Super Kings (CSK) | L4: 3072 | V4: Win by Runs | W4: 37
A5: Delhi Capitals (DC) | B5: 16 | C5: 5 | K5: Delhi Capitals (DC) | L5: 1632 | V5: Win by Wickets | W5: 23
A6: Kolkata Knight Riders (KKR) | B6: 15 | C6: 9 | K6: Kolkata Knight Riders (KKR) | L6: 3230
A7: Mumbai Indians (MI) | B7: 16 | C7: 6 | K7: Mumbai Indians (MI) | L7: 2142
A8: Punjab Kings (PBKS) | B8: 13 | C8: 6 | K8: Punjab Kings (PBKS) | L8: 1952
A9: Rajasthan Royals (RR) | B9: 16 | C9: 8 | K9: Rajasthan Royals (RR) | L9: 2830
A10: Royal Challengers Bengaluru (RCB) | B10: 15 | C10: 7 | K10: Royal Challengers Bengaluru (RCB) | L10: 2626
A11: Sunrisers Hyderabad (SRH) | B11: 15 | C11: 10 | K11: Sunrisers Hyderabad (SRH) | L11: 3460
A14: =SUM(B4:B11) -> 120 | C14: =IFERROR(SUM(C4:C11),"NA") -> 60
L15: =IFERROR(SUM(L4:L11),"NA") -> 20944
A16: =IFERROR(COUNTA(A4:A11),"NA") -> 8
A20: Row Labels | B20: Team Total Wins | K20: Row Labels | L20: Total Wickets
A21: Delhi Capitals (DC) | B21: 5 | K21: Chennai Super Kings (CSK) | L21: 126
A22: Mumbai Indians (MI) | B22: 6 | K22: Delhi Capitals (DC) | L22: 64
A23: Punjab Kings (PBKS) | B23: 6 | K23: Kolkata Knight Riders (KKR) | L23: 114
A24: Royal Challengers Bengaluru (RCB) | B24: 7 | K24: Mumbai Indians (MI) | L24: 77
A25: Rajasthan Royals (RR) | B25: 8 | K25: Punjab Kings (PBKS) | L25: 89
A26: Kolkata Knight Riders (KKR) | B26: 9 | K26: Rajasthan Royals (RR) | L26: 109
A27: Chennai Super Kings (CSK) | B27: 9 | K27: Royal Challengers Bengaluru (RCB) | L27: 88
A28: Sunrisers Hyderabad (SRH) | B28: 10 | K28: Sunrisers Hyderabad (SRH) | L28: 132
L32: =IFERROR(SUM(L21:L28),"NA") -> 799
A37: Row Labels | B37: Matches Played
A38: Rajiv Gandhi Int. Stadium | B38: 8
A39: Wankhede Stadium | B39: 8
A40: Eden Gardens | B40: 8
A41: M. A. Chidambaram Stadium | B41: 8
A42: Sawai Mansingh Stadium | B42: 7
A43: Maharaja Yadavindra Singh Int. Cricket Stadium | B43: 7
A44: Arun Jaitley Stadium | B44: 7
A45: M. Chinnaswamy Stadium | B45: 7
B51: =SUM(B38:B45) -> 60

Sheet Team_Performance_Dashboard

Sheet Player_Performance_Dashboard

Sheet Player_Summary
A3: Row Labels | B3: Sum of Runs | O3: Row Labels | P3: Avgs Strike Rate
A4: Mohammed Siraj | B4: 25 | O4: Abhishek Sharma | P4: 162.96296
A5: Dinesh Karthik | B5: 42 | O5: Andre Russell | P5: 184.84848
A6: Sunil Narine | B6: 61 | O6: Daryl Mitchell | P6: 147.16981
A7: Jitesh Sharma | B7: 82 | O7: David Warner | P7: 146.34146
A8: Tilak Varma | B8: 82 | O8: Dinesh Karthik | P8: 200
A9: Hardik Pandya | B9: 90 | O9: Glenn Maxwell | P9: 168.33333
A10: Mitchell Marsh | B10: 95 | O10: Hardik Pandya | P10: 142.85714
A11: Glenn Maxwell | B11: 101 | O11: Heinrich Klaasen | P11: 191.37931
A12: Ishan Kishan | B12: 123 | O12: Ishan Kishan | P12: 144.70588
A13: Daryl Mitchell | B13: 156 | O13: Jitesh Sharma | P13: 146.42857
A14: Andre Russell | B14: 183 | O14: Jos Buttler | P14: 162.87425
A15: Shivam Dube | B15: 191 | O15: Liam Livingstone | P15: 156.66667
... A25: Virat Kohli | B25: 572 | O25: Yashasvi Jaiswal | P25: 157.80347
O26: Grand Total | P26: 161.5894
O29: =IFERROR(AVERAGE(GETPIVOTDATA("[Measures].[Avgs Strike Rate]",$O$3)),"NA") -> 161.5894
A30: =INDEX(A2:A100, MATCH(MAX(B2:B100), B2:B100, 0)) -> Virat Kohli
A34: =IFERROR(_xlfn.XLOOKUP(MAX(B4:B25),B4:B25,A4:A25),"NA") -> Virat Kohli
O37: Row Labels | P37: Avgs Economy
O38: Andre Russell | P38: 9.25
O39: Arshdeep Singh | P39: 7.1
O40: Axar Patel | P40: 6.5
O41: Bhuvneshwar Kumar | P41: 7.9166667
O42: Deepak Chahar | P42: 6.5625
O43: Glenn Maxwell | P43: 7
O44: Hardik Pandya | P44: 7.5
O45: Jasprit Bumrah | P45: 7.3676471
O46: Kagiso Rabada | P46: 8.75
O47: Kuldeep Yadav | P47: 4.9166667
O48: Matheesha Pathirana | P48: 5.25
O49: Mitchell Marsh | P49: 10
... O55: Grand Total | P55: 7.2867587
A56: Row Labels | B56: Sum of Wickets
A57: Mitchell Marsh | B57: 2
A58: Glenn Maxwell | B58: 2
A59: Kagiso Rabada | B59: 3
A60: Hardik Pandya | B60: 3 | O60: =IFERROR(AVERAGE(GETPIVOTDATA("[Measures].[Avgs Economy]",$O$37)),"NA") -> 7.2867587
A61: Matheesha Pathirana | B61: 3
A62: Axar Patel | B62: 4
A63: Kuldeep Yadav | B63: 5
...

Sheet fact_match
A1: Match_ID | B1: Date | C1: Venue_ID | D1: Team1_ID | E1: Team2_ID | F1: Toss_Winner | G1: Match_Winner | H1: Man_of_Match | I1: Team1_Runs | J1: Team2_Runs | K1: Team1_Wickets | L1: Team2_Wickets | M1: Overs_Team1 | N1: Overs_Team2
A2: M001 | B2: 45738 | C2: V02 | D2: T02 | E2: T03 | F2: T02 | G2: T02 | H2: P006 | I2: 192 | J2: 174 | K2: 4 | L2: 8 | M2: 20 | N2: 20
A3: M002 | B3: 45739 | C3: V08 | D3: T08 | E3: T05 | F3: T08 | G3: T08 | H3: P033 | I3: 184 | J3: 183 | K3: 7 | L3: 9 | M3: 20 | N3: 20
A4: M003 | B4: 45739 | C4: V04 | D4: T04 | E4: T07 | F4: T07 | G4: T04 | H4: P015 | I4: 208 | J4: 198 | K4: 6 | L4: 7 | M4: 20 | N4: 20
A5: M004 | B5: 45740 | C5: V06 | D5: T06 | E5: T01 | F5: T01 | G5: T06 | H5: P022 | I5: 193 | J5: 165 | K5: 5 | L5: 10 | M5: 20 | N5: 17.2
A6: M005 | B6: 45741 | C6: V03 | D6: T03 | E6: T06 | F6: T03 | G6: T06 | H6: P025 | I6: 181 | J6: 185 | K6: 5 | L6: 4 | M6: 20 | N6: 19.3
A7: M006 | B7: 45742 | C7: V05 | D7: T05 | E7: T04 | F7: T05 | G7: T04 | H7: P016 | I7: 164 | J7: 165 | K7: 8 | L7: 3 | M7: 20 | N7: 18.4
A8: M007 | B8: 45743 | C8: V02 | D8: T02 | E8: T07 | F8: T07 | G8: T02 | H8: P007 | I8: 178 | J8: 169 | K8: 6 | L8: 9 | M8: 20 | N8: 20
A9: M008 | B9: 45744 | C9: V01 | D9: T01 | E9: T08 | F9: T01 | G9: T08 | H9: P032 | I9: 154 | J9: 155 | K9: 10 | L9: 3 | M9: 19.5 | N9: 17
A10: M009 | B10: 45745 | C10: V04 | D10: T04 | E10: T03 | F10: T03 | G10: T04 | H10: P017 | I10: 171 | J10: 156 | K10: 5 | L10: 9 | M10: 20 | N10: 18.3
A11: M010 | B11: 45746 | C11: V06 | D11: T06 | E11: T05 | F11: T05 | G11: T05 | H11: P019 | I11: 149 | J11: 150 | K11: 9 | L11: 4 | M11: 20 | N11: 18.1
A12: M011 | B12: 45747 | C12: V07 | D12: T07 | E12: T01 | F12: T01 | G12: T07 | H12: P026 | I12: 177 | J12: 152 | K12: 7 | L12: 8 | M12: 20 | N12: 18.4
A13: M012 | B13: 45748 | C13: V08 | D13: T08 | E13: T02 | F13: T02 | G13: T02 | H13: P008 | I13: 161 | J13: 162 | K13: 8 | L13: 6 | M13: 20 | N13: 19.2
... A61: M060 | B61: 45796 | C61: V06 | D61: T06 | E61: T01 | F61: T05 | G61: T07 | H61: P027 | I61: 155 | J61: 156 | K61: 10 | L61: 6 | M61: 20 | N61: 19.4

Sheet dim_venue
A1: Venue_ID | B1: Venue_Name | C1: City | D1: Capacity
A2: V01 | B2: Wankhede Stadium | C2: Mumbai | D2: 33108
A3: V02 | B3: M. A. Chidambaram Stadium | C3: Chennai | D3: 38000
A4: V03 | B4: M. Chinnaswamy Stadium | C4: Bengaluru | D4: 42000
A5: V04 | B5: Eden Gardens | C5: Kolkata | D5: 68000
A6: V05 | B6: Arun Jaitley Stadium | C6: Delhi | D6: 41820
A7: V06 | B7: Sawai Mansingh Stadium | C7: Jaipur | D7: 30000
A8: V07 | B8: Maharaja Yadavindra Singh Int. Cricket Stadium | C8: Mohali | D8: 38000
A9: V08 | B9: Rajiv Gandhi Int. Stadium | C9: Hyderabad | D9: 39200
A10: V09 | B10: Narendra Modi Stadium | C10: Ahmedabad | D10: 132000
A11: V10 | B11: Bharat Ratna Shri Atal Bihari Vajpayee Ekana Cricket Stadium | C11: Lucknow | D11: 50000

Sheet dim_team
A1: Team_ID | B1: Team_Name | C1: Captain | D1: Coach | E1: Home_Ground | F1: City | G1: Owner
A2: T01 | B2: Mumbai Indians (MI) | C2: Rohit Sharma | D2: Mark Boucher | E2: Wankhede Stadium | F2: Mumbai | G2: Reliance Industries
A3: T02 | B3: Chennai Super Kings (CSK) | C3: Ruturaj Gaikwad | D3: Stephen Fleming | E3: M. A. Chidambaram Stadium | F3: Chennai | G3: India Cements
A4: T03 | B4: Royal Challengers Bengaluru (RCB) | C4: Faf du Plessis | D4: Andy Flower | E4: M. Chinnaswamy Stadium | F4: Bengaluru | G4: United Spirits
A5: T04 | B5: Kolkata Knight Riders (KKR) | C5: Shreyas Iyer | D5: Chandrakant Pandit | E5: Eden Gardens | F5: Kolkata | G5: Shah Rukh Khan
A6: T05 | B6: Delhi Capitals (DC) | C6: Rishabh Pant | D6: Ricky Ponting | E6: Arun Jaitley Stadium | F6: Delhi | G6: JSW Group
A7: T06 | B7: Rajasthan Royals (RR) | C7: Sanju Samson | D7: Kumar Sangakkara | E7: Sawai Mansingh Stadium | F7: Jaipur | G7: Manoj Badale
A8: T07 | B8: Punjab Kings (PBKS) | C8: Shikhar Dhawan | D8: Trevor Bayliss | E8: Maharaja Yadavindra Singh Int. Cricket Stadium | F8: Mohali | G8: Preity Zinta
A9: T08 | B9: Sunrisers Hyderabad (SRH) | C9: Pat Cummins | D9: Daniel Vettori | E9: Rajiv Gandhi Int. Stadium | F9: Hyderabad | G9: Sun TV Network

Sheet dim_player
A1: Player_ID | B1: Player_Name | C1: Team_ID | D1: Role | E1: Nationality | F1: Age | G1: Batting_Style | H1: Bowling_Style | I1: Column1
A2: P001 | B2: Suryakumar Yadav | C2: T01 | D2: Batsman | E2: Indian | F2: 33 | G2: Right-hand Bat | H2: Off-break | I2: =COUNTIF(dim_player!A:A, A2) -> 1
A3: P002 | B3: Jasprit Bumrah | C3: T01 | D3: Bowler | E3: Indian | F3: 31 | G3: Right-hand Bat | H3: Right-arm Fast | I3: =COUNTIF(dim_player!A:A, A3) -> 1
A4: P003 | B4: Ishan Kishan | C4: T01 | D4: Wicketkeeper | E4: Indian | F4: 26 | G4: Left-hand Bat | H4: None | I4: =COUNTIF(dim_player!A:A, A4) -> 1
A5: P004 | B5: Tilak Varma | C5: T01 | D5: All-Rounder | E5: Indian | F5: 22 | G5: Left-hand Bat | H5: Off-break | I5: =COUNTIF(dim_player!A:A, A5) -> 1
A6: P005 | B6: Hardik Pandya | C6: T01 | D6: All-Rounder | E6: Indian | F6: 31 | G6: Right-hand Bat | H6: Right-arm Medium | I6: =COUNTIF(dim_player!A:A, A6) -> 1
A7: P006 | B7: Shivam Dube | C7: T02 | D7: All-Rounder | E7: Indian | F7: 31 | G7: Left-hand Bat | H7: Right-arm Medium | I7: =COUNTIF(dim_player!A:A, A7) -> 1
A8: P007 | B8: Deepak Chahar | C8: T02 | D8: Bowler | E8: Indian | F8: 32 | G8: Right-hand Bat | H8: Right-arm Medium-Fast | I8: =COUNTIF(dim_player!A:A, A8) -> 1
A9: P008 | B9: Daryl Mitchell | C9: T02 | D9: All-Rounder | E9: New Zealander | F9: 33 | G9: Right-hand Bat | H9: Right-arm Medium | I9: =COUNTIF(dim_player!A:A, A9) -> 1
A10: P009 | B10: Matheesha Pathirana | C10: T02 | D10: Bowler | E10: Sri Lankan | F10: 22 | G10: Right-hand Bat | H10: Right-arm Fast | I10: =COUNTIF(dim_player!A:A, A10) -> 1
A11: P010 | B11: Virat Kohli | C11: T03 | D11: Batsman | E11: Indian | F11: 36 | G11: Right-hand Bat | H11: Right-arm Medium | I11: =COUNTIF(dim_player!A:A, A11) -> 1
A12: P011 | B12: Mohammed Siraj | C12: T03 | D12: Bowler | E12: Indian | F12: 31 | G12: Right-hand Bat | H12: Right-arm Fast | I12: =COUNTIF(dim_player!A:A, A12) -> 1
A13: P012 | B13: Glenn Maxwell | C13: T03 | D13: All-Rounder | E13: Australian | F13: 36 | G13: Right-hand Bat | H13: Off-break | I13: =COUNTIF(dim_player!A:A, A13) -> 1
... A34: P033 | B34: Travis Head | C34: T08 | D34: Batsman | E34: Australian | F34: 31 | G34: Left-hand Bat | H34: Off-break | I34: =COUNTIF(dim_player!A:A, A34) -> 1
